Workbook

Sheet 统计
A1: 指标 | B1: 数值
A2: 节点数 | B2: =COUNTA('节点表_v0.2'!$A$2:$A$248)
A3: 原始关系数 | B3: =COUNTIF('关系表_v0.2'!$D$2:$D$954,"CONTAINS")+COUNTIF('关系表_v0.2'!$D$2:$D$954,"BELONGS_TO_COURSE")+COUNTIF('关系表_v0.2'!$D$2:$D$954,"BELONGS_TO_TOPIC")
A4: 新增语义关系数 | B4: =B5-B3
A5: 关系总数 | B5: =COUNTA('关系表_v0.2'!$A$2:$A$954)
A6: 关系数_BELONGS_TO_COURSE | B6: =COUNTIF('关系表_v0.2'!$D$2:$D$954,"BELONGS_TO_COURSE")
A7: 关系数_BELONGS_TO_TOPIC | B7: =COUNTIF('关系表_v0.2'!$D$2:$D$954,"BELONGS_TO_TOPIC")
A8: 关系数_CONTAINS | B8: =COUNTIF('关系表_v0.2'!$D$2:$D$954,"CONTAINS")
A9: 关系数_IS_A | B9: =COUNTIF('关系表_v0.2'!$D$2:$D$954,"IS_A")
A10: 关系数_PREREQUISITE_OF | B10: =COUNTIF('关系表_v0.2'!$D$2:$D$954,"PREREQUISITE_OF")
A11: 关系数_HAS_PROPERTY | B11: =COUNTIF('关系表_v0.2'!$D$2:$D$954,"HAS_PROPERTY")
A12: 关系数_HAS_OPERATION | B12: =COUNTIF('关系表_v0.2'!$D$2:$D$954,"HAS_OPERATION")
A13: 关系数_IMPLEMENTED_BY | B13: =COUNTIF('关系表_v0.2'!$D$2:$D$954,"IMPLEMENTED_BY")
A14: 关系数_USES | B14: =COUNTIF('关系表_v0.2'!$D$2:$D$954,"USES")
A15: 关系数_APPLIED_IN | B15: =COUNTIF('关系表_v0.2'!$D$2:$D$954,"APPLIED_IN")
A16: 关系数_SOLVES | B16: =COUNTIF('关系表_v0.2'!$D$2:$D$954,"SOLVES")
A17: 关系数_ENSURES | B17: =COUNTIF('关系表_v0.2'!$D$2:$D$954,"ENSURES")
A18: 关系数_CAUSES | B18: =COUNTIF('关系表_v0.2'!$D$2:$D$954,"CAUSES")
A19: 关系数_OPTIMIZES | B19: =COUNTIF('关系表_v0.2'!$D$2:$D$954,"OPTIMIZES")
A20: 关系数_EVALUATED_BY | B20: =COUNTIF('关系表_v0.2'!$D$2:$D$954,"EVALUATED_BY")
A21: 关系数_COMPARE_WITH | B21: =COUNTIF('关系表_v0.2'!$D$2:$D$954,"COMPARE_WITH")
A22: 关系数_CONFUSED_WITH | B22: =COUNTIF('关系表_v0.2'!$D$2:$D$954,"CONFUSED_WITH")
A23: 关系数_ILLUSTRATED_BY | B23: =COUNTIF('关系表_v0.2'!$D$2:$D$954,"ILLUSTRATED_BY")

Sheet 节点表_v0.2
A1: node_id | B1: name | C1: entity_type | D1: course | E1: topic | F1: definition | G1: alias | H1: difficulty | I1: importance | J1: source | K1: source_section | L1: book_page | M1: evidence_text
A2: CN_CRS_001 | B2: 计算机网络 | C2: Course | D2: 计算机网络 | F2: 由分散自治的计算机系统经通信设备和线路互连，并依靠协议实现资源共享与信息传递的系统。 | G2: 计网,网络,Computer Network | H2: 3 | I2: 5 | J2: 王道2027计网，内容简介，PDF页2 | K2: 内容简介 | L2: 2 | M2: 教材内容简介说明本书包括网络体系结构、物理层、数据链路层、网络层、传输层、应用层等内容；本节点概括为：由分散自治的计算机系统经通信设备和线路互连，并依靠协议实现资源共享与信息传递的系统。
A3: CN_TOP_001 | B3: 第1章 计算机网络体系结构 | C3: Topic | D3: 计算机网络 | E3: 第1章 计算机网络体系结构 | F3: 建立计算机网络概念、组成、交换方式、性能指标、分层结构与参考模型的基础认识。 | H3: 3 | I3: 5 | J3: 王道2027计网，第1章 计算机网络体系结构，教材p1（PDF页12） | K3: 第1章 计算机网络体系结构 | L3: 1 | M3: 教材在“第1章 计算机网络体系结构”中出现或讲解“第1章 计算机网络体系结构”；本节点概括为：建立计算机网络概念、组成、交换方式、性能指标、分层结构与参考模型的基础认识。
A4: CN_TOP_002 | B4: 计算机网络概述 | C4: Topic | D4: 计算机网络 | E4: 第1章 计算机网络体系结构 | F4: 从整体上介绍计算机网络概述的基本对象、作用、结构和常见考点。 | H4: 3 | I4: 4 | J4: 王道2027计网，计算机网络概述，教材p1（PDF页12） | K4: 计算机网络概述 | L4: 1 | M4: 教材在“计算机网络概述”中出现或讲解“计算机网络概述”；本节点概括为：从整体上介绍计算机网络概述的基本对象、作用、结构和常见考点。
A5: CN_TOP_003 | B5: 计算机网络的概念 | C5: Concept | D5: 计算机网络 | E5: 第1章 计算机网络体系结构 | F5: 说明网络、互连网、互联网、ISP等基本术语及计算机网络的基本定义。 | H5: 2 | I5: 4 | J5: 王道2027计网，计算机网络的概念，教材p1（PDF页12） | K5: 计算机网络的概念 | L5: 1 | M5: 教材在“计算机网络的概念”中出现或讲解“计算机网络的概念”；本节点概括为：说明网络、互连网、互联网、ISP等基本术语及计算机网络的基本定义。
A6: CN_TOP_004 | B6: 计算机网络的组成 | C6: Concept | D6: 计算机网络 | E6: 第1章 计算机网络体系结构 | F6: 从组成部分、工作方式和功能组成三个角度说明网络硬件、软件、协议、边缘/核心和通信/资源子网。 | H6: 2 | I6: 4 | J6: 王道2027计网，计算机网络的组成，教材p2（PDF页13） | K6: 计算机网络的组成 | L6: 2 | M6: 教材在“计算机网络的组成”中出现或讲解“计算机网络的组成”；本节点概括为：从组成部分、工作方式和功能组成三个角度说明网络硬件、软件、协议、边缘/核心和通信/资源子网。
A7: CN_TOP_005 | B7: 计算机网络的功能 | C7: Concept | D7: 计算机网络 | E7: 第1章 计算机网络体系结构 | F7: 概括数据通信、资源共享、分布式处理、可靠性提升和负载均衡等网络作用。 | H7: 2 | I7: 4 | J7: 王道2027计网，计算机网络的功能，教材p2（PDF页13） | K7: 计算机网络的功能 | L7: 2 | M7: 教材在“计算机网络的功能”中出现或讲解“计算机网络的功能”；本节点概括为：概括数据通信、资源共享、分布式处理、可靠性提升和负载均衡等网络作用。
A8: CN_TOP_006 | B8: 数据通信 | C8: Concept | D8: 计算机网络 | E8: 第1章 计算机网络体系结构 | F8: 属于“计算机网络的功能”下的核心知识点，用于理解第1章 计算机网络体系结构中的相关原理和考点。 | H8: 3 | I8: 4 | J8: 王道2027计网，数据通信，教材p2（PDF页13） | K8: 数据通信 | L8: 2 | M8: 教材在“数据通信”中出现或讲解“数据通信”；本节点概括为：属于“计算机网络的功能”下的核心知识点，用于理解第1章 计算机网络体系结构中的相关原理和考点。
A9: CN_TOP_007 | B9: 资源共享 | C9: Concept | D9: 计算机网络 | E9: 第1章 计算机网络体系结构 | F9: 属于“计算机网络的功能”下的核心知识点，用于理解第1章 计算机网络体系结构中的相关原理和考点。 | H9: 3 | I9: 4 | J9: 王道2027计网，资源共享，教材p2（PDF页13） | K9: 资源共享 | L9: 2 | M9: 教材在“资源共享”中出现或讲解“资源共享”；本节点概括为：属于“计算机网络的功能”下的核心知识点，用于理解第1章 计算机网络体系结构中的相关原理和考点。
A10: CN_TOP_008 | B10: 分布式处理 | C10: Concept | D10: 计算机网络 | E10: 第1章 计算机网络体系结构 | F10: 属于“计算机网络的功能”下的核心知识点，用于理解第1章 计算机网络体系结构中的相关原理和考点。 | H10: 3 | I10: 4 | J10: 王道2027计网，分布式处理，教材p2（PDF页13） | K10: 分布式处理 | L10: 2 | M10: 教材在“分布式处理”中出现或讲解“分布式处理”；本节点概括为：属于“计算机网络的功能”下的核心知识点，用于理解第1章 计算机网络体系结构中的相关原理和考点。
A11: CN_TOP_009 | B11: 提高可靠性 | C11: Concept | D11: 计算机网络 | E11: 第1章 计算机网络体系结构 | F11: 属于“计算机网络的功能”下的核心知识点，用于理解第1章 计算机网络体系结构中的相关原理和考点。 | H11: 4 | I11: 4 | J11: 王道2027计网，提高可靠性，教材p2（PDF页13） | K11: 提高可靠性 | L11: 2 | M11: 教材在“提高可靠性”中出现或讲解“提高可靠性”；本节点概括为：属于“计算机网络的功能”下的核心知识点，用于理解第1章 计算机网络体系结构中的相关原理和考点。
A12: CN_TOP_010 | B12: 负载均衡 | C12: Concept | D12: 计算机网络 | E12: 第1章 计算机网络体系结构 | F12: 属于“计算机网络的功能”下的核心知识点，用于理解第1章 计算机网络体系结构中的相关原理和考点。 | H12: 3 | I12: 4 | J12: 王道2027计网，负载均衡，教材p3（PDF页14） | K12: 负载均衡 | L12: 3 | M12: 教材在“负载均衡”中出现或讲解“负载均衡”；本节点概括为：属于“计算机网络的功能”下的核心知识点，用于理解第1章 计算机网络体系结构中的相关原理和考点。
A13: CN_TOP_011 | B13: 电路交换、报文交换与分组交换 | C13: DataStructure | D13: 计算机网络 | E13: 第1章 计算机网络体系结构 | F13: 描述电路交换、报文交换与分组交换的数据组织方式、字段含义或标识作用。 | H13: 3 | I13: 5 | J13: 王道2027计网，电路交换、报文交换与分组交换，教材p3（PDF页14） | K13: 电路交换、报文交换与分组交换 | L13: 3 | M13: 教材在“电路交换、报文交换与分组交换”中出现或讲解“电路交换、报文交换与分组交换”；本节点概括为：描述电路交换、报文交换与分组交换的数据组织方式、字段含义或标识作用。
A14: CN_TOP_012 | B14: 电路交换 | C14: Mechanism | D14: 计算机网络 | E14: 第1章 计算机网络体系结构 | F14: 通信前建立端到端专用物理通路，通信期间独占线路，适合连续、大量、实时的数据传输。 | H14: 3 | I14: 4 | J14: 王道2027计网，电路交换，教材p3（PDF页14） | K14: 电路交换 | L14: 3 | M14: 教材在“电路交换”中出现或讲解“电路交换”；本节点概括为：通信前建立端到端专用物理通路，通信期间独占线路，适合连续、大量、实时的数据传输。
... A30: CN_TOP_028 | B30: OSI参考模型和TCP/IP模型 | C30: Model | D30: 计算机网络 | E30: 第1章 计算机网络体系结构 | F30: 对比七层OSI参考模型和四/五层TCP/IP模型，说明各层功能及协议体系。 | H30: 4 | I30: 5 | J30: 王道2027计网，OSI参考模型和TCP/IP模型，教材p17（PDF页28） | K30: OSI参考模型和TCP/IP模型 | L30: 17 | M30: 教材在“OSI参考模型和TCP/IP模型”中出现或讲解“OSI参考模型和TCP/IP模型”；本节点概括为：对比七层OSI参考模型和四/五层TCP/IP模型，说明各层功能及协议体系。
A31: CN_TOP_029 | B31: OSI参考模型 | C31: Model | D31: 计算机网络 | E31: 第1章 计算机网络体系结构 | F31: 用于抽象描述OSI参考模型的组成层次、交互关系或工作方式。 | G31: ISO/OSI模型, OSI七层模型 | H31: 3 | I31: 5 | J31: 王道2027计网，OSI参考模型，教材p17（PDF页28） | K31: OSI参考模型 | L31: 17 | M31: 教材在“OSI参考模型”中出现或讲解“OSI参考模型”；本节点概括为：用于抽象描述OSI参考模型的组成层次、交互关系或工作方式。
A32: CN_TOP_030 | B32: TCP/IP模型 | C32: Model | D32: 计算机网络 | E32: 第1章 计算机网络体系结构 | F32: 用于抽象描述TCP/IP模型的组成层次、交互关系或工作方式。 | G32: TCP/IP参考模型, Internet协议栈 | H32: 4 | I32: 5 | J32: 王道2027计网，TCP/IP模型，教材p20（PDF页31） | K32: TCP/IP模型 | L32: 20 | M32: 教材在“TCP/IP模型”中出现或讲解“TCP/IP模型”；本节点概括为：用于抽象描述TCP/IP模型的组成层次、交互关系或工作方式。
A33: CN_TOP_031 | B33: TCP/IP模型与OSI参考模型的比较 | C33: Model | D33: 计算机网络 | E33: 第1章 计算机网络体系结构 | F33: 用于抽象描述TCP/IP模型与OSI参考模型的比较的组成层次、交互关系或工作方式。 | H33: 4 | I33: 5 | J33: 王道2027计网，TCP/IP模型与OSI参考模型的比较，教材p21（PDF页32） | K33: TCP/IP模型与OSI参考模型的比较 | L33: 21 | M33: 教材在“TCP/IP模型与OSI参考模型的比较”中出现或讲解“TCP/IP模型与OSI参考模型的比较”；本节点概括为：用于抽象描述TCP/IP模型与OSI参考模型的比较的组成层次、交互关系或工作方式。
A34: CN_TOP_032 | B34: 第2章 物理层 | C34: Topic | D34: 计算机网络 | E34: 第2章 物理层 | F34: 研究比特在物理介质上的传输，包括信道容量、编码调制、传输介质和物理层设备。 | H34: 3 | I34: 5 | J34: 王道2027计网，第2章 物理层，教材p30（PDF页41） | K34: 第2章 物理层 | L34: 30 | M34: 教材在“第2章 物理层”中出现或讲解“第2章 物理层”；本节点概括为：研究比特在物理介质上的传输，包括信道容量、编码调制、传输介质和物理层设备。
A35: CN_TOP_033 | B35: 通信基础 | C35: Topic | D35: 计算机网络 | E35: 第2章 物理层 | F35: 属于“第2章 物理层”下的核心知识点，用于理解第2章 物理层中的相关原理和考点。 | H35: 3 | I35: 4 | J35: 王道2027计网，通信基础，教材p30（PDF页41） | K35: 通信基础 | L35: 30 | M35: 教材在“通信基础”中出现或讲解“通信基础”；本节点概括为：属于“第2章 物理层”下的核心知识点，用于理解第2章 物理层中的相关原理和考点。
A36: CN_TOP_034 | B36: 通信基础：基本概念 | C36: Concept | D36: 计算机网络 | E36: 第2章 物理层 | F36: 梳理通信基础：基本概念涉及的基础术语、组成对象和相互关系。 | H36: 2 | I36: 4 | J36: 王道2027计网，通信基础：基本概念，教材p30（PDF页41） | K36: 通信基础：基本概念 | L36: 30 | M36: 教材在“通信基础：基本概念”中出现或讲解“通信基础：基本概念”；本节点概括为：梳理通信基础：基本概念涉及的基础术语、组成对象和相互关系。
A37: CN_TOP_035 | B37: 数据、信号与码元 | C37: DataStructure | D37: 计算机网络 | E37: 第2章 物理层 | F37: 属于“通信基础：基本概念”下的核心知识点，用于理解第2章 物理层中的相关原理和考点。 | H37: 3 | I37: 4 | J37: 王道2027计网，数据、信号与码元，教材p30（PDF页41） | K37: 数据、信号与码元 | L37: 30 | M37: 教材在“数据、信号与码元”中出现或讲解“数据、信号与码元”；本节点概括为：属于“通信基础：基本概念”下的核心知识点，用于理解第2章 物理层中的相关原理和考点。
A38: CN_TOP_036 | B38: 信源、信道与信宿 | C38: Concept | D38: 计算机网络 | E38: 第2章 物理层 | F38: 属于“通信基础：基本概念”下的核心知识点，用于理解第2章 物理层中的相关原理和考点。 | H38: 3 | I38: 4 | J38: 王道2027计网，信源、信道与信宿，教材p30（PDF页41） | K38: 信源、信道与信宿 | L38: 30 | M38: 教材在“信源、信道与信宿”中出现或讲解“信源、信道与信宿”；本节点概括为：属于“通信基础：基本概念”下的核心知识点，用于理解第2章 物理层中的相关原理和考点。
A39: CN_TOP_037 | B39: 速率、波特与带宽 | C39: Metric | D39: 计算机网络 | E39: 第2章 物理层 | F39: 属于“通信基础：基本概念”下的核心知识点，用于理解第2章 物理层中的相关原理和考点。 | H39: 3 | I39: 4 | J39: 王道2027计网，速率、波特与带宽，教材p31（PDF页42） | K39: 速率、波特与带宽 | L39: 31 | M39: 教材在“速率、波特与带宽”中出现或讲解“速率、波特与带宽”；本节点概括为：属于“通信基础：基本概念”下的核心知识点，用于理解第2章 物理层中的相关原理和考点。
A40: CN_TOP_038 | B40: 信道的极限容量 | C40: Metric | D40: 计算机网络 | E40: 第2章 物理层 | F40: 属于“通信基础”下的核心知识点，用于理解第2章 物理层中的相关原理和考点。 | H40: 5 | I40: 4 | J40: 王道2027计网，信道的极限容量，教材p31（PDF页42） | K40: 信道的极限容量 | L40: 31 | M40: 教材在“信道的极限容量”中出现或讲解“信道的极限容量”；本节点概括为：属于“通信基础”下的核心知识点，用于理解第2章 物理层中的相关原理和考点。
A41: CN_TOP_039 | B41: 奈奎斯特定理（奈氏准则） | C41: Algorithm | D41: 计算机网络 | E41: 第2章 物理层 | F41: 属于“信道的极限容量”下的核心知识点，用于理解第2章 物理层中的相关原理和考点。 | H41: 3 | I41: 4 | J41: 王道2027计网，奈奎斯特定理（奈氏准则），教材p32（PDF页43） | K41: 奈奎斯特定理（奈氏准则） | L41: 32 | M41: 教材在“奈奎斯特定理（奈氏准则）”中出现或讲解“奈奎斯特定理（奈氏准则）”；本节点概括为：属于“信道的极限容量”下的核心知识点，用于理解第2章 物理层中的相关原理和考点。
A42: CN_TOP_040 | B42: 香农定理 | C42: Algorithm | D42: 计算机网络 | E42: 第2章 物理层 | F42: 描述有噪声信道在给定带宽和信噪比条件下的极限信息传输速率。 | G42: Shannon theorem | H42: 3 | I42: 4 | J42: 王道2027计网，香农定理，教材p32（PDF页43） | K42: 香农定理 | L42: 32 | M42: 教材在“香农定理”中出现或讲解“香农定理”；本节点概括为：描述有噪声信道在给定带宽和信噪比条件下的极限信息传输速率。
A43: CN_TOP_041 | B43: 编码与调制 | C43: Mechanism | D43: 计算机网络 | E43: 第2章 物理层 | F43: 研究数据与信号之间的变换，包括数字编码、模拟编码和调制方式。 | H43: 4 | I43: 4 | J43: 王道2027计网，编码与调制，教材p33（PDF页44） | K43: 编码与调制 | L43: 33 | M43: 教材在“编码与调制”中出现或讲解“编码与调制”；本节点概括为：研究数据与信号之间的变换，包括数字编码、模拟编码和调制方式。
A44: CN_TOP_042 | B44: 数字数据编码为数字信号 | C44: DataStructure | D44: 计算机网络 | E44: 第2章 物理层 | F44: 说明数字数据编码为数字信号的基本原理、处理流程和适用场景。 | H44: 4 | I44: 4 | J44: 王道2027计网，数字数据编码为数字信号，教材p33（PDF页44） | K44: 数字数据编码为数字信号 | L44: 33 | M44: 教材在“数字数据编码为数字信号”中出现或讲解“数字数据编码为数字信号”；本节点概括为：说明数字数据编码为数字信号的基本原理、处理流程和适用场景。
A45: CN_TOP_043 | B45: 模拟数据编码为数字信号 | C45: DataStructure | D45: 计算机网络 | E45: 第2章 物理层 | F45: 说明模拟数据编码为数字信号的基本原理、处理流程和适用场景。 | H45: 4 | I45: 4 | J45: 王道2027计网，模拟数据编码为数字信号，教材p34（PDF页45） | K45: 模拟数据编码为数字信号 | L45: 34 | M45: 教材在“模拟数据编码为数字信号”中出现或讲解“模拟数据编码为数字信号”；本节点概括为：说明模拟数据编码为数字信号的基本原理、处理流程和适用场景。
A46: CN_TOP_044 | B46: 数字数据调制为模拟信号 | C46: DataStructure | D46: 计算机网络 | E46: 第2章 物理层 | F46: 说明数字数据调制为模拟信号的基本原理、处理流程和适用场景。 | H46: 4 | I46: 4 | J46: 王道2027计网，数字数据调制为模拟信号，教材p34（PDF页45） | K46: 数字数据调制为模拟信号 | L46: 34 | M46: 教材在“数字数据调制为模拟信号”中出现或讲解“数字数据调制为模拟信号”；本节点概括为：说明数字数据调制为模拟信号的基本原理、处理流程和适用场景。
A47: CN_TOP_045 | B47: 模拟数据直接传输为模拟信号 | C47: DataStructure | D47: 计算机网络 | E47: 第2章 物理层 | F47: 属于“编码与调制”下的核心知识点，用于理解第2章 物理层中的相关原理和考点。 | H47: 3 | I47: 4 | J47: 王道2027计网，模拟数据直接传输为模拟信号，教材p35（PDF页46） | K47: 模拟数据直接传输为模拟信号 | L47: 35 | M47: 教材在“模拟数据直接传输为模拟信号”中出现或讲解“模拟数据直接传输为模拟信号”；本节点概括为：属于“编码与调制”下的核心知识点，用于理解第2章 物理层中的相关原理和考点。
A48: CN_TOP_046 | B48: 传输介质 | C48: Topic | D48: 计算机网络 | E48: 第2章 物理层 | F48: 属于“第2章 物理层”下的核心知识点，用于理解第2章 物理层中的相关原理和考点。 | H48: 3 | I48: 4 | J48: 王道2027计网，传输介质，教材p42（PDF页53） | K48: 传输介质 | L48: 42 | M48: 教材在“传输介质”中出现或讲解“传输介质”；本节点概括为：属于“第2章 物理层”下的核心知识点，用于理解第2章 物理层中的相关原理和考点。
A49: CN_TOP_047 | B49: 双绞线、同轴电缆、光纤与无线传输介质 | C49: ComputingObject | D49: 计算机网络 | E49: 第2章 物理层 | F49: 属于“传输介质”下的核心知识点，用于理解第2章 物理层中的相关原理和考点。 | H49: 3 | I49: 4 | J49: 王道2027计网，双绞线、同轴电缆、光纤与无线传输介质，教材p42（PDF页53） | K49: 双绞线、同轴电缆、光纤与无线传输介质 | L49: 42 | M49: 教材在“双绞线、同轴电缆、光纤与无线传输介质”中出现或讲解“双绞线、同轴电缆、光纤与无线传输介质”；本节点概括为：属于“传输介质”下的核心知识点，用于理解第2章 物理层中的相关原理和考点。
A50: CN_TOP_048 | B50: 双绞线 | C50: ComputingObject | D50: 计算机网络 | E50: 第2章 物理层 | F50: 由两根绝缘铜线绞合而成的有线传输介质，常用于以太网接入。 | H50: 3 | I50: 4 | J50: 王道2027计网，双绞线，教材p42（PDF页53） | K50: 双绞线 | L50: 42 | M50: 教材在“双绞线”中出现或讲解“双绞线”；本节点概括为：由两根绝缘铜线绞合而成的有线传输介质，常用于以太网接入。
A51: CN_TOP_049 | B51: 同轴电缆 | C51: ComputingObject | D51: 计算机网络 | E51: 第2章 物理层 | F51: 具有同心导体结构的有线介质，抗干扰能力较强。 | H51: 3 | I51: 4 | J51: 王道2027计网，同轴电缆，教材p42（PDF页53） | K51: 同轴电缆 | L51: 42 | M51: 教材在“同轴电缆”中出现或讲解“同轴电缆”；本节点概括为：具有同心导体结构的有线介质，抗干扰能力较强。
A52: CN_TOP_050 | B52: 光纤 | C52: ComputingObject | D52: 计算机网络 | E52: 第2章 物理层 | F52: 利用光信号传输数据的介质，具有带宽高、损耗低、抗电磁干扰强等特点。 | H52: 3 | I52: 4 | J52: 王道2027计网，光纤，教材p42（PDF页53） | K52: 光纤 | L52: 42 | M52: 教材在“光纤”中出现或讲解“光纤”；本节点概括为：利用光信号传输数据的介质，具有带宽高、损耗低、抗电磁干扰强等特点。
A53: CN_TOP_051 | B53: 无线传输介质 | C53: ComputingObject | D53: 计算机网络 | E53: 第2章 物理层 | F53: 利用电磁波在自由空间中传输数据的介质，包括无线电、微波和红外等。 | H53: 3 | I53: 4 | J53: 王道2027计网，无线传输介质，教材p43（PDF页54） | K53: 无线传输介质 | L53: 43 | M53: 教材在“无线传输介质”中出现或讲解“无线传输介质”；本节点概括为：利用电磁波在自由空间中传输数据的介质，包括无线电、微波和红外等。
A54: CN_TOP_052 | B54: 物理层接口的特性 | C54: Property | D54: 计算机网络 | E54: 第2章 物理层 | F54: 概括物理层接口的特性的主要性质、优势、限制和适用条件。 | H54: 3 | I54: 4 | J54: 王道2027计网，物理层接口的特性，教材p44（PDF页55） | K54: 物理层接口的特性 | L54: 44 | M54: 教材在“物理层接口的特性”中出现或讲解“物理层接口的特性”；本节点概括为：概括物理层接口的特性的主要性质、优势、限制和适用条件。
... A72: CN_TOP_070 | B72: 奇偶检验码 | C72: Concept | D72: 计算机网络 | E72: 第3章 数据链路层 | F72: 属于“检错编码”下的核心知识点，用于理解第3章 数据链路层中的相关原理和考点。 | H72: 3 | I72: 4 | J72: 王道2027计网，奇偶检验码，教材p57（PDF页68） | K72: 奇偶检验码 | L72: 57 | M72: 教材在“奇偶检验码”中出现或讲解“奇偶检验码”；本节点概括为：属于“检错编码”下的核心知识点，用于理解第3章 数据链路层中的相关原理和考点。
...

Sheet 关系表_v0.2
A1: edge_id | B1: head | C1: head_name | D1: relation_type | E1: tail | F1: tail_name | G1: reason | H1: source | I1: confidence | J1: source_section | K1: book_page | L1: evidence_text
A2: CN_E_0001 | B2: CN_CRS_001 | C2: 计算机网络 | D2: CONTAINS | E2: CN_TOP_001 | F2: 第1章 计算机网络体系结构 | G2: 课程由各章节构成。 | H2: 王道2027计网，第1章 计算机网络体系结构，教材p1（PDF页12） | I2: 1.0 | J2: 第1章 计算机网络体系结构 | K2: 1 | L2: “计算机网络”与“第1章 计算机网络体系结构”之间建立“CONTAINS”关系。依据：课程由各章节构成。
A3: CN_E_0002 | B3: CN_TOP_001 | C3: 第1章 计算机网络体系结构 | D3: BELONGS_TO_COURSE | E3: CN_CRS_001 | F3: 计算机网络 | G3: 章节属于本课程。 | H3: 王道2027计网，内容简介，PDF页2 | I3: 1.0 | J3: 内容简介 | K3: 2 | L3: “第1章 计算机网络体系结构”与“计算机网络”之间建立“BELONGS_TO_COURSE”关系。依据：章节属于本课程。
A4: CN_E_0003 | B4: CN_CRS_001 | C4: 计算机网络 | D4: CONTAINS | E4: CN_TOP_032 | F4: 第2章 物理层 | G4: 课程由各章节构成。 | H4: 王道2027计网，第2章 物理层，教材p30（PDF页41） | I4: 1.0 | J4: 第2章 物理层 | K4: 30 | L4: “计算机网络”与“第2章 物理层”之间建立“CONTAINS”关系。依据：课程由各章节构成。
A5: CN_E_0004 | B5: CN_TOP_032 | C5: 第2章 物理层 | D5: BELONGS_TO_COURSE | E5: CN_CRS_001 | F5: 计算机网络 | G5: 章节属于本课程。 | H5: 王道2027计网，内容简介，PDF页2 | I5: 1.0 | J5: 内容简介 | K5: 2 | L5: “第2章 物理层”与“计算机网络”之间建立“BELONGS_TO_COURSE”关系。依据：章节属于本课程。
A6: CN_E_0005 | B6: CN_CRS_001 | C6: 计算机网络 | D6: CONTAINS | E6: CN_TOP_056 | F6: 第3章 数据链路层 | G6: 课程由各章节构成。 | H6: 王道2027计网，第3章 数据链路层，教材p50（PDF页61） | I6: 1.0 | J6: 第3章 数据链路层 | K6: 50 | L6: “计算机网络”与“第3章 数据链路层”之间建立“CONTAINS”关系。依据：课程由各章节构成。
A7: CN_E_0006 | B7: CN_TOP_056 | C7: 第3章 数据链路层 | D7: BELONGS_TO_COURSE | E7: CN_CRS_001 | F7: 计算机网络 | G7: 章节属于本课程。 | H7: 王道2027计网，内容简介，PDF页2 | I7: 1.0 | J7: 内容简介 | K7: 2 | L7: “第3章 数据链路层”与“计算机网络”之间建立“BELONGS_TO_COURSE”关系。依据：章节属于本课程。
A8: CN_E_0007 | B8: CN_CRS_001 | C8: 计算机网络 | D8: CONTAINS | E8: CN_TOP_115 | F8: 第4章 网络层 | G8: 课程由各章节构成。 | H8: 王道2027计网，第4章 网络层，教材p127（PDF页138） | I8: 1.0 | J8: 第4章 网络层 | K8: 127 | L8: “计算机网络”与“第4章 网络层”之间建立“CONTAINS”关系。依据：课程由各章节构成。
A9: CN_E_0008 | B9: CN_TOP_115 | C9: 第4章 网络层 | D9: BELONGS_TO_COURSE | E9: CN_CRS_001 | F9: 计算机网络 | G9: 章节属于本课程。 | H9: 王道2027计网，内容简介，PDF页2 | I9: 1.0 | J9: 内容简介 | K9: 2 | L9: “第4章 网络层”与“计算机网络”之间建立“BELONGS_TO_COURSE”关系。依据：章节属于本课程。
A10: CN_E_0009 | B10: CN_CRS_001 | C10: 计算机网络 | D10: CONTAINS | E10: CN_TOP_183 | F10: 第5章 传输层 | G10: 课程由各章节构成。 | H10: 王道2027计网，第5章 传输层，教材p224（PDF页235） | I10: 1.0 | J10: 第5章 传输层 | K10: 224 | L10: “计算机网络”与“第5章 传输层”之间建立“CONTAINS”关系。依据：课程由各章节构成。
A11: CN_E_0010 | B11: CN_TOP_183 | C11: 第5章 传输层 | D11: BELONGS_TO_COURSE | E11: CN_CRS_001 | F11: 计算机网络 | G11: 章节属于本课程。 | H11: 王道2027计网，内容简介，PDF页2 | I11: 1.0 | J11: 内容简介 | K11: 2 | L11: “第5章 传输层”与“计算机网络”之间建立“BELONGS_TO_COURSE”关系。依据：章节属于本课程。
A12: CN_E_0011 | B12: CN_CRS_001 | C12: 计算机网络 | D12: CONTAINS | E12: CN_TOP_214 | F12: 第6章 应用层 | G12: 课程由各章节构成。 | H12: 王道2027计网，第6章 应用层，教材p267（PDF页278） | I12: 1.0 | J12: 第6章 应用层 | K12: 267 | L12: “计算机网络”与“第6章 应用层”之间建立“CONTAINS”关系。依据：课程由各章节构成。
... A954: CN_E_0953 | B954: CN_TOP_244 | C954: HTTP的报文结构 | D954: ILLUSTRATED_BY | E954: CN_TOP_246 | F954: HTTP请求报文举例 | G954: 请求报文例子用于说明HTTP报文结构字段。 | H954: 王道2027计网，HTTP的报文结构，教材p292（PDF页303） | I954: 0.9 | J954: HTTP的报文结构 | K954: 292 | L954: “HTTP的报文结构”与“HTTP请求报文举例”之间建立“ILLUSTRATED_BY”关系。依据：请求报文例子用于说明HTTP报文结构字段。

Sheet 实体类型
A1: entity_type | B1: 中文名 | C1: 含义 | D1: 示例
A2: Course | B2: 课程 | C2: 一门完整课程 | D2: 计算机网络
A3: Topic | B3: 章节/主题 | C3: 课程中的章节或知识模块 | D3: 计算机网络体系结构、数据链路层、网络层
A4: Concept | B4: 概念 | C4: 普通知识概念 | D4: 协议、服务、接口、虚电路、数据报
A5: ComputingObject | B5: 计算对象/系统对象 | C5: 课程中被操作、管理或传输的对象 | D5: 路由器、交换机、主机、域名服务器
A6: DataStructure | B6: 数据结构 | C6: 组织数据或标识对象的结构 | D6: IP数据报、MAC帧、路由表、端口号
A7: Algorithm | B7: 算法/策略 | C7: 有明确步骤的算法或策略 | D7: 距离-向量算法、链路状态算法、慢开始
A8: Mechanism | B8: 机制/原理 | C8: 系统运行机制或工作原理 | D8: 分组交换、NAT、ARP、滑动窗口
A9: Protocol | B9: 协议 | C9: 通信或协作规则 | D9: IP、TCP、UDP、DNS、HTTP、SMTP
A10: Model | B10: 模型 | C10: 抽象模型或理论模型 | D10: OSI参考模型、TCP/IP模型、客户/服务器模型
A11: Operation | B11: 操作 | C11: 对对象执行的动作 | D11: 分片、转发、确认、重传
A12: SyntaxElement | B12: 语法/语句 | C12: 报文或协议中的语法元素 | D12: HTTP请求行、首部字段
... A17: Example | B17: 例题/案例 | C17: 具体题目、案例或实验 | D17: HTTP请求报文举例、子网划分应用举例

Sheet 关系类型
A1: relation_type | B1: 中文名 | C1: 方向规则 | D1: 示例
A2: BELONGS_TO_COURSE | B2: 属于课程 | C2: 知识点 → 课程 | D2: TCP → 计算机网络
A3: BELONGS_TO_TOPIC | B3: 属于主题/章节 | C3: 知识点 → 章节 | D3: IPv4地址 → 网络层
A4: CONTAINS | B4: 包含 | C4: 大概念 → 小概念 | D4: IPv4 → IPv4地址
A5: IS_A | B5: 是一种 | C5: 子类 → 父类 | D5: UDP → 无连接服务
A6: PREREQUISITE_OF | B6: 前置知识 | C6: 先学的 → 后学的 | D6: 数据链路层 → 网络层
A7: HAS_PROPERTY | B7: 具有性质 | C7: 对象 → 性质 | D7: HTTP → 无状态
A8: HAS_OPERATION | B8: 具有操作 | C8: 对象 → 操作 | D8: TCP → TCP连接建立
A9: IMPLEMENTED_BY | B9: 实现方式 | C9: 抽象概念 → 实现方式 | D9: 可靠传输机制 → GBN
A10: USES | B10: 使用 | C10: A → B | D10: HTTP → TCP
A11: APPLIED_IN | B11: 应用于 | C11: 知识点 → 应用场景 | D11: CSMA/CD → 以太网
A12: SOLVES | B12: 解决 | C12: 方法/算法 → 问题 | D12: NAT → IPv4地址不足
... A19: ILLUSTRATED_BY | B19: 举例说明 | C19: 知识点 → 案例 | D19: HTTP报文结构 → HTTP请求报文举例

Sheet 修改说明
A1: 项目 | B1: 说明 | C1: 是否完成 | D1: 备注
A2: 修正日期 | B2: 2026-06-19 | C2: 是 | D2: 按质量检查报告修正
A3: 课程 | B3: 计算机网络 | C3: 是 | D3: ID 前缀：CN_
A4: 保留类型体系 | B4: 实体类型表、关系类型表未新增、未删除、未改名 | C4: 是 | D4: 只修正节点表/关系表中的数据错误
A5: 修改项 | B5: 补全课程节点 `计算机网络` 的 course 字段为 `计算机网络`。 | C5: 是
A6: 修改项 | B6: 为节点 ID 和关系 ID 增加课程前缀 `CN_`，并同步更新关系表中的 head/tail 引用，避免五门课合并时 ID 冲突。 | C6: 是
A7: 验证项 | B7: node_id/edge_id 已加课程前缀，关系表 head/tail 已同步 | C7: 是 | D7: 用于五门课合并
